Workbook

Sheet masterlist_log
A1: PROJE KODU | B1: PROJE ADI | C1: MÜŞTERİ | D1: Tip | E1: WBS Code | F1: Origin | G1: Shipment ID | H1: No | I1: HS Code (GTIP) | J1: Malzeme Tanımı | K1: Material Description | L1: Qty 1 | M1: Unit 1 | N1: Qty 2 | O1: Unit 2 | P1: Unit Weight (kg) | Q1: Length (mm) | R1: Width (mm) | S1: Height-Thickness (mm) | T1: Total Weight (kg) | U1: Total Lenght (m) | V1: Vendor | W1: Deliverable Type | X1: Cargo Group | Y1: Package Type | Z1: Package Qty | AA1: Package No | AB1: Net Weight (kg) | AC1: Gross Weight (kg)
A2: VMP-S01064 | B2: ATP_5000m3_Bingazi | C2: ATP | D2: Main | E2: 3.1.2 | F2: İSKENDERUN | G2: iskSHT_shp1 | H2: 1 | J2: 12x1500x8000 mm ST37 Sac | L2: 136 | M2: pcs | P2: 1130.33 | Q2: 8000 | R2: 1500 | S2: 12 | T2: =P2*L2 -> 153724.88 | U2: - | V2: ABC METAL | X2: BT_steel_plates | Y2: Loose
A3: VMP-S01065 | B3: ATP_5000m3_Bingazi | C3: ATP | D3: Main | E3: 3.1.2 | F3: İSKENDERUN | G3: iskSHT_shp1 | H3: 2 | J3: 12x1500x6900 mm ST37 Sac | L3: 80 | M3: pcs | P3: 974.94 | Q3: 6900 | R3: 1500 | S3: 12 | T3: =P3*L3 -> 77995.2 | U3: - | V3: ABC METAL | X3: BT_steel_plates | Y3: Loose
A4: VMP-S01066 | B4: ATP_5000m3_Bingazi | C4: ATP | D4: Main | E4: 3.1.2 | F4: İSKENDERUN | G4: iskSHT_shp1 | H4: 3 | J4: 10x1500x6900 mm ST37 Sac | L4: 80 | M4: pcs | P4: 812.44 | Q4: 6900 | R4: 1500 | S4: 10 | T4: =P4*L4 -> 64995.2 | U4: - | V4: ABC METAL | X4: BT_steel_plates | Y4: Loose
A5: VMP-S01067 | B5: ATP_5000m3_Bingazi | C5: ATP | D5: Main | E5: 3.1.2 | F5: İSKENDERUN | G5: iskSHT_shp1 | H5: 4 | J5: 8x1500x6900 mm ST37 Sac | L5: 80 | M5: pcs | P5: 649.95 | Q5: 6900 | R5: 1500 | S5: 8 | T5: =P5*L5 -> 51996 | U5: - | V5: ABC METAL | X5: BT_steel_plates | Y5: Loose
A6: VMP-S01064-2 | B6: ATP_SITE_Bingazi | C6: ATP | D6: Main | E6: 3.1.9 | F6: İSKENDERUN | G6: iskSHT_shp1 | H6: 5 | J6: 8x1500x6000 mm St37 Sac | L6: 18 | M6: pcs | P6: 565.44 | Q6: 6000 | R6: 1500 | S6: 8 | T6: =P6*L6 -> 10177.92 | U6: - | V6: ABC METAL | X6: ST_steel_plates | Y6: Loose
A7: VMP-S01068 | B7: ATP_5000m3_Bingazi | C7: ATP | D7: Main | E7: 3.1.2 | F7: İSKENDERUN | G7: iskSHT_shp1 | H7: 6 | J7: 6x1500x6900 mm ST37 Sac | L7: 120 | M7: pcs | P7: 487.49 | Q7: 6900 | R7: 1500 | S7: 6 | T7: =P7*L7 -> 58498.8 | U7: - | V7: ABC METAL | X7: BT_steel_plates | Y7: Loose
A8: VMP-S01064-2 | B8: ATP_SITE_Bingazi | C8: ATP | D8: Main | E8: 3.1.10 | F8: İSKENDERUN | G8: iskSHT_shp1 | H8: 7 | J8: 6x1500x6000 mm St37 Sac | L8: 12 | M8: pcs | P8: 423.75 | Q8: 6000 | R8: 1500 | S8: 6 | T8: =P8*L8 -> 5085 | U8: - | V8: ABC METAL | X8: ST_steel_plates | Y8: Loose
A9: VMP-S01069 | B9: ATP_5000m3_Bingazi | C9: ATP | D9: Main | E9: 3.1.2 | F9: İSKENDERUN | G9: iskSHT_shp1 | H9: 8 | J9: 4x1500x8000 mm ST37 Sac | L9: 136 | M9: pcs | P9: 376.8 | Q9: 8000 | R9: 1500 | S9: 4 | T9: =P9*L9 -> 51244.8 | U9: - | V9: ABC METAL | X9: BT_steel_plates | Y9: Loose
A10: VMP-S01064-2 | B10: ATP_SITE_Bingazi | C10: ATP | D10: Main | E10: 3.1.2 | F10: İSKENDERUN | G10: iskSHT_shp1 | H10: 9 | J10: 4x1500x6000 mm St37 Sac | L10: 8 | M10: pcs | P10: 282.63 | Q10: 6000 | R10: 1500 | S10: 4 | T10: =P10*L10 -> 2261.04 | U10: - | V10: ABC METAL | X10: ST_steel_plates | Y10: Loose
A11: VMP-S01070 | B11: ATP_5000m3_Bingazi | C11: ATP | D11: Main | E11: 3.1.2 | F11: İSKENDERUN | G11: iskSHT_shp1 | H11: 10 | J11: 3x1500x8000 mm ST37 Sac | L11: 136 | M11: pcs | P11: 282.63 | Q11: 8000 | R11: 1500 | S11: 3 | T11: =P11*L11 -> 38437.68 | U11: - | V11: ABC METAL | X11: BT_steel_plates | Y11: Loose
A12: VMP-S01071 | B12: ATP_5000m3_Bingazi | C12: ATP | D12: Main | E12: 3.4 | F12: KARABÜK | G12: karabükRM_shp3 | H12: 11 | J12: 240 NPI 6mt | L12: 192 | M12: pcs | P12: 216 | Q12: 6000 | R12: 106 | S12: 240 | T12: =P12*L12 -> 41472 | U12: =L12*6 -> 1152 | V12: MC METAL | X12: BT_material | Y12: Bundle
A13: VMP-S01071 | B13: ATP_5000m3_Bingazi | C13: ATP | D13: Main | E13: 3.4 | F13: KARABÜK | G13: karabükRM_shp3 | H13: 11 | J13: 240 NPI 12mt | L13: 96 | M13: pcs | P13: 432 | Q13: 6000 | R13: 106 | S13: 240 | T13: =P13*L13 -> 41472 | U13: =L13*6 -> 576 | V13: MC METAL | X13: BT_material | Y13: Bundle
A14: VMP-S01072 | B14: ATP_5000m3_Bingazi | C14: ATP | D14: Main | E14: 3.4 | F14: KARABÜK | G14: karabükRM_shp3 | H14: 12 | J14: 180 NPI 6 mt | L14: 60 | M14: pcs | P14: 131.4 | Q14: 6000 | R14: 82 | S14: 180 | T14: =P14*L14 -> 7884 | U14: =L14*6 -> 360 | V14: MC METAL | X14: BT_material | Y14: Bundle
A15: VMP-S01072 | B15: ATP_5000m3_Bingazi | C15: ATP | D15: Main | E15: 3.4 | F15: KARABÜK | G15: karabükRM_shp3 | H15: 12 | J15: 180 NPI 12 mt | L15: 30 | M15: pcs | P15: 264 | Q15: 6000 | R15: 82 | S15: 180 | T15: =P15*L15 -> 7920 | U15: =L15*6 -> 180 | V15: MC METAL | X15: BT_material | Y15: Bundle
A16: VMP-S01073 | B16: ATP_5000m3_Bingazi | C16: ATP | D16: Main | E16: 3.4 | F16: KARABÜK | G16: vimpoRM_shp4 | H16: 13 | J16: 80 NPI 6 mt | L16: 100 | M16: pcs | P16: 35.64 | Q16: 6000 | R16: 42 | S16: 80 | T16: =P16*L16 -> 3564 | U16: =L16*6 -> 600 | V16: MC METAL | X16: BT_material | Y16: Bundle
A17: VMP-S01064-2 | B17: ATP_SITE_Bingazi | C17: ATP | D17: Main | E17: 3.4 | F17: ANKARA | G17: vimpoRM_shp4 | H17: 14 | J17: 80 NPI 6mt | L17: 36 | M17: pcs | P17: 35.64 | Q17: 6000 | R17: 42 | S17: 80 | T17: =P17*L17 -> 1283.04 | U17: =L17*6 -> 216 | V17: MC METAL | X17: ST_material | Y17: Bundle
A18: VMP-S01074 | B18: ATP_5000m3_Bingazi | C18: ATP | D18: Main | E18: 3.4 | F18: ANKARA | G18: vimpoRM_shp4 | H18: 15 | J18: 60x40x2 mm Kutu Profil | L18: 600 | M18: pcs | P18: 18.08 | Q18: 6000 | R18: 40 | S18: 60x2 | T18: =P18*L18 -> 10848 | U18: =L18*6 -> 3600 | V18: MC METAL | X18: BT_material | Y18: Bundle
A19: VMP-S01075 | B19: ATP_5000m3_Bingazi | C19: ATP | D19: Main | E19: 3.4 | F19: ANKARA | G19: vimpoRM_shp4 | H19: 16 | J19: 40x20x2 mm Kutu Profil | L19: 200 | M19: pcs | P19: 10.55 | Q19: 6000 | R19: 20 | S19: 40x2 | T19: =P19*L19 -> 2110 | U19: =L19*6 -> 1200 | V19: MC METAL | X19: BT_material | Y19: Bundle
A20: VMP-S01077 | B20: ATP_5000m3_Bingazi | C20: ATP | D20: Main | E20: 3.4 | F20: ANKARA | G20: vimpoRM_shp4 | H20: 17 | J20: 30x3 mm Silme 6 mt | L20: 840 | M20: pcs | P20: 4.24 | Q20: 6000 | R20: 30 | S20: 3 | T20: =P20*L20 -> 3561.6 | U20: =L20*6 -> 5040 | V20: MC METAL | X20: BT_material | Y20: Bundle
A21: VMP-S01078 | B21: ATP_5000m3_Bingazi | C21: ATP | D21: Main | E21: 3.4 | F21: ANKARA | G21: vimpoRM_shp4 | H21: 18 | J21: 50x5 mm Silme 6 mt | L21: 96 | M21: pcs | P21: 11.78 | Q21: 6000 | R21: 50 | S21: 5 | T21: =P21*L21 -> 1130.88 | U21: =L21*6 -> 576 | V21: MC METAL | X21: BT_material | Y21: Bundle
A22: VMP-S01081 | B22: ATP_5000m3_Bingazi | C22: ATP | D22: Main | E22: 3.4 | F22: ANKARA | G22: vimpoRM_shp4 | H22: 19 | J22: 50x50x5 mm Köşebent | L22: 40 | M22: pcs | P22: 22.37 | Q22: 6000 | R22: 50 | S22: 50x5 | T22: =P22*L22 -> 894.8 | U22: =L22*6 -> 240 | V22: MC METAL | X22: BT_material | Y22: Bundle
A23: VMP-S01083 | B23: ATP_5000m3_Bingazi | C23: ATP | D23: Main | E23: 3.4 | F23: ANKARA | G23: vimpoRM_shp4 | H23: 20 | J23: 10x50 lama 6 mt | L23: 60 | M23: pcs | P23: 23.55 | Q23: 6000 | R23: 50 | S23: 10 | T23: =P23*L23 -> 1413 | U23: =L23*6 -> 360 | V23: MC METAL | X23: BT_material | Y23: Bundle
A25: VMP-S01076 | B25: ATP_5000m3_Bingazi | C25: ATP | D25: Main | E25: 3.2.2 | F25: ADANA | G25: adanaPPS_shp2 | H25: 21 | J25: 1" 2 mm dikişli boru 6 mt | L25: 312 | M25: mt | P25: 2.19 | V25: NORM BORU | X25: BT_pipe
A26: VMP-S01079 | B26: ATP_5000m3_Bingazi | C26: ATP | D26: Main | E26: 3.2.2 | F26: ADANA | G26: adanaPPS_shp3 | H26: 22 | J26: 8'' 4 mm dikişli boru 6 mt | L26: 120 | M26: mt | P26: 118.4 | V26: NORM BORU | X26: BT_pipe
A27: VMP-S01087 | B27: ATP_5000m3_Bingazi | C27: ATP | D27: Main | E27: 3.2.2 | F27: ADANA | G27: adanaPPS_shp4 | H27: 23 | J27: 2" 60,30x3,2 mm P235GH-TC1 çelik çekme boru 12mt | L27: 10500 | M27: mt | V27: NORM BORU | X27: BT_pipe
A28: VMP-S01064-2 | B28: ATP_SITE_Bingazi | C28: ATP | D28: Main | E28: 3.2.2 | F28: ADANA | G28: adanaPPS_shp5 | H28: 24 | J28: 8'' 4 mm dikişli boru 6 mt | L28: 24 | M28: mt | T28: 509 | V28: NORM BORU | X28: ST_pipe
A29: VMP-S01064-2 | B29: ATP_SITE_Bingazi | C29: ATP | D29: Main | E29: 3.2.2 | F29: ADANA | G29: adanaPPS_shp6 | H29: 25 | J29: 2" 3,2 mm çelik çekme boru P235GH | L29: 800 | M29: mt | T29: 3590 | V29: NORM BORU | X29: ST_pipe
A31: VMP-S01080 | B31: ATP_5000m3_Bingazi | C31: ATP | D31: Main | F31: ANKARA | H31: 17 | J31: Baklavalı sacdan basamak-ÇİZİM VAR-DAR TARAFA 8" BORUYA GÖRE KAYNAK AĞIZLI | L31: 220 | M31: pcs | V31: BAYDOĞANLAR | X31: BT_material
A32: VMP-S01082 | B32: ATP_5000m3_Bingazi | C32: ATP | D32: Main | F32: ANKARA | H32: 19 | J32: ETEK SACI - 3x100x2000 mm St37 sac | L32: 140 | M32: pcs | V32: BAYDOĞANLAR | X32: BT_material
A33: VMP-S01088 | B33: ATP_5000m3_Bingazi | C33: ATP | D33: Main | F33: ANKARA | H33: 25 | J33: 2'' 180° Dirsek SCH40 | L33: 840 | M33: pcs | P33: 1.8 | V33: TARGET | X33: BT_material
A34: VMP-S01064-2 | B34: ATP_SITE_Bingazi | C34: ATP | D34: Main | F34: ANKARA | H34: 6 | J34: 2'' 180° Dirsek SCH40 | L34: 100 | M34: pcs | P34: 1.8 | V34: TARGET | X34: BT_material
A35: VMP-S01089 | B35: ATP_5000m3_Bingazi | C35: ATP | D35: Main | F35: ANKARA | H35: 26 | J35: Trapez Vidası 5,5X25 MM | L35: 60 | M35: kg | P35: 60 | T35: 60 | V35: FT MAKİNE | X35: BT_material
A36: VMP-S01090 | B36: ATP_5000m3_Bingazi | C36: ATP | D36: Main | F36: ANKARA | H36: 27 | J36: Antipas boya 25 kg | L36: 16 | M36: can | P36: 25 | T36: =P36*L36 -> 400 | V36: FT MAKİNE | X36: BT_material
A38: VMP-S01064-2 | B38: ATP_SITE_Bingazi | C38: ATP | D38: Main | F38: ANKARA | H38: 1 | J38: KAYNAKÇI ELDİVENİ | L38: 180 | M38: pcs | V38: FT MAKİNE | X38: siteequipment
A39: VMP-S01064-2 | B39: ATP_SITE_Bingazi | C39: ATP | D39: Main | F39: ANKARA | H39: 2 | J39: SARI MONTAJ ELDİVENİ BEYBİ | L39: 300 | M39: pcs | V39: FT MAKİNE | X39: siteequipment
A40: VMP-S01064-2 | B40: ATP_SITE_Bingazi | C40: ATP | D40: Main | F40: ANKARA | H40: 3 | J40: BAŞ MASKESİ | L40: 10 | M40: pcs | V40: FT MAKİNE | X40: siteequipment
A41: VMP-S01064-2 | B41: ATP_SITE_Bingazi | C41: ATP | D41: Main | F41: ANKARA | H41: 4 | J41: MASKE CAMI SİYAH | L41: 100 | M41: pcs | V41: FT MAKİNE | X41: siteequipment
A42: VMP-S01064-2 | B42: ATP_SITE_Bingazi | C42: ATP | D42: Main | F42: ANKARA | H42: 5 | J42: TAŞLAMA GÖZLÜĞÜ | L42: 20 | M42: pcs | V42: FT MAKİNE | X42: siteequipment
A43: VMP-S01064-2 | B43: ATP_SITE_Bingazi | C43: ATP | D43: Main | F43: ANKARA | H43: 6 | J43: 4*2,5 TTR KABLO 380 GRUP PRİZ 380 ERKEK 20 MT | L43: 4 | M43: pcs | V43: FT MAKİNE | X43: siteequipment
...

Sheet isk_shp1
A1: Shipment ID | B1: Container No | C1: Malzeme 1 | D1: Qty | E1: Unit | F1: Unit Weight (kg) | G1: Total Weight (kg) | H1: Malzeme 2 | I1: Adet 2 | J1: Malzeme 3 | K1: Adet 3 | L1: Malzeme 4 | M1: Adet 4 | N1: Toplam Cotainer Weight (kg) | O1: Payload Dif (kg) | P1: Durum
A2: iskenderun_shp1 | B2: C01 | C2: 12x1500x8000 mm ST37 Sac | D2: 23 | E2: pcs | F2: =masterlist_log!P2 -> 1130.33 | G2: =D2*F2 -> 25997.59 | N2: =G2 -> 25997.59 | O2: =N2-26000 -> -2.41 | P2: Limit Altı
A3: iskenderun_shp1 | B3: C02 | C3: 12x1500x8000 mm ST37 Sac | D3: 23 | E3: pcs | F3: =masterlist_log!P2 -> 1130.33 | G3: =D3*F3 -> 25997.59 | N3: =G3 -> 25997.59 | O3: =N3-26000 -> -2.41 | P3: Limit Altı
A4: iskenderun_shp1 | B4: C03 | C4: 12x1500x8000 mm ST37 Sac | D4: 23 | E4: pcs | F4: =masterlist_log!P2 -> 1130.33 | G4: =D4*F4 -> 25997.59 | N4: =G4 -> 25997.59 | O4: =N4-26000 -> -2.41 | P4: Limit Altı
A5: iskenderun_shp1 | B5: C04 | C5: 12x1500x8000 mm ST37 Sac | D5: 23 | E5: pcs | F5: =masterlist_log!P2 -> 1130.33 | G5: =D5*F5 -> 25997.59 | N5: =G5 -> 25997.59 | O5: =N5-26000 -> -2.41 | P5: Limit Altı
A6: iskenderun_shp1 | B6: C05 | C6: 12x1500x8000 mm ST37 Sac | D6: 23 | E6: pcs | F6: =masterlist_log!P2 -> 1130.33 | G6: =D6*F6 -> 25997.59 | N6: =G6 -> 25997.59 | O6: =N6-26000 -> -2.41 | P6: Limit Altı
A7: iskenderun_shp1 | B7: C06 | C7: 10x1500x6900 mm ST37 Sac | D7: 32 | E7: pcs | F7: =masterlist_log!P4 -> 812.44 | G7: =D7*F7 -> 25998.08 | N7: =G7 -> 25998.08 | O7: =N7-26000 -> -1.92 | P7: Limit Altı
A8: iskenderun_shp1 | B8: C07 | C8: 10x1500x6900 mm ST37 Sac | D8: 32 | E8: pcs | F8: =masterlist_log!P4 -> 812.44 | G8: =D8*F8 -> 25998.08 | N8: =G8 -> 25998.08 | O8: =N8-26000 -> -1.92 | P8: Limit Altı
A9: iskenderun_shp1 | B9: C08 | C9: 8x1500x6900 mm ST37 Sac | D9: 40 | E9: pcs | F9: =masterlist_log!P5 -> 649.95 | G9: =D9*F9 -> 25998 | N9: =G9 -> 25998 | O9: =N9-26000 -> -2 | P9: Sınırda
A10: iskenderun_shp1 | B10: C09 | C10: 8x1500x6900 mm ST37 Sac | D10: 40 | E10: pcs | F10: =masterlist_log!P5 -> 649.95 | G10: =D10*F10 -> 25998 | N10: =G10 -> 25998 | O10: =N10-26000 -> -2 | P10: Sınırda
A11: iskenderun_shp1 | B11: C10 | C11: 4x1500x8000 mm ST37 Sac | D11: 69 | E11: pcs | F11: =masterlist_log!P9 -> 376.8 | G11: =D11*F11 -> 25999.2 | N11: =G11 -> 25999.2 | O11: =N11-26000 -> -0.8 | P11: Limit Altı
A12: iskenderun_shp1 | B12: C11 | C12: 12x1500x6900 mm ST37 Sac | D12: 26 | E12: pcs | F12: =masterlist_log!P3 -> 974.94 | G12: =D12*F12 -> 25348.44 | N12: =SUM(G12:G13) -> 25998.39 | O12: =N12-26000 -> -1.61 | P12: Limit Altı
C13: 8x1500x6900 mm ST37 Sac | D13: 1 | E13: pcs | F13: =masterlist_log!P5 -> 649.95 | G13: =D13*F13 -> 649.95
A14: iskenderun_shp1 | B14: C12 | C14: 12x1500x6900 mm ST37 Sac | D14: 26 | E14: pcs | F14: =masterlist_log!P3 -> 974.94 | G14: =D14*F14 -> 25348.44 | N14: =SUM(G14:G15) -> 25998.39 | O14: =N14-26000 -> -1.61 | P14: Limit Altı
C15: 8x1500x6900 mm ST37 Sac | D15: 1 | E15: pcs | F15: =masterlist_log!P5 -> 649.95 | G15: =D15*F15 -> 649.95
A16: iskenderun_shp1 | B16: C13 | C16: 12x1500x6900 mm ST37 Sac | D16: 26 | E16: pcs | F16: =masterlist_log!P3 -> 974.94 | G16: =D16*F16 -> 25348.44 | N16: =SUM(G16:G17) -> 25998.39 | O16: -1.62 | P16: Limit Altı
C17: 8x1500x6900 mm ST37 Sac | D17: 1 | E17: pcs | F17: =masterlist_log!P5 -> 649.95 | G17: =D17*F17 -> 649.95
A18: iskenderun_shp1 | B18: C14 | C18: 10x1500x6900 mm ST37 Sac | D18: 16 | E18: pcs | F18: =masterlist_log!P4 -> 812.44 | G18: =D18*F18 -> 12999.04 | N18: =SUM(G18:G19) -> 25998.04 | O18: -1 | P18: Limit Altı
C19: 8x1500x6900 mm ST37 Sac | D19: 20 | E19: pcs | F19: =masterlist_log!P5 -> 649.95 | G19: =D19*F19 -> 12999
A20: iskenderun_shp1 | B20: C15 | C20: 3x1500x8000 mm ST37 Sac | D20: 89 | E20: pcs | F20: =masterlist_log!P11 -> 282.63 | G20: =D20*F20 -> 25154.07 | N20: =SUM(G20:G21) -> 26284.59 | O20: =N20-26000 -> 284.59 | P20: Az Aşım
C21: 4x1500x6000 mm ST37 Sac | D21: 4 | E21: pcs | F21: =masterlist_log!P10 -> 282.63 | G21: =D21*F21 -> 1130.52
A22: iskenderun_shp1 | B22: C16 | C22: 6x1500x6900 mm ST37 Sac | D22: 53 | E22: pcs | F22: =masterlist_log!P7 -> 487.49 | G22: =D22*F22 -> 25836.97 | N22: =SUM(G22:G23) -> 26119.6 | O22: =N22-26000 -> 119.6 | P22: Az Aşım
C23: 4x1500x6000 mm ST37 Sac | D23: 1 | E23: pcs | F23: =masterlist_log!P10 -> 282.63 | G23: =D23*F23 -> 282.63
A24: iskenderun_shp1 | B24: C17 | C24: 4x1500x8000 mm ST37 Sac | D24: 34 | E24: pcs | F24: =masterlist_log!P9 -> 376.8 | G24: =D24*F24 -> 12811.2 | N24: =SUM(G24:G26) -> 26094.81 | O24: =N24-26000 -> 94.81 | P24: Az Aşım
C25: 3x1500x8000 mm ST37 Sac | D25: 46 | E25: pcs | F25: =masterlist_log!P11 -> 282.63 | G25: =D25*F25 -> 13000.98
C26: 4x1500x6000 mm ST37 Sac | D26: 1 | E26: pcs | F26: =masterlist_log!P10 -> 282.63 | G26: =D26*F26 -> 282.63
A27: iskenderun_shp1 | B27: C18 | C27: 8x1500x6900 mm ST37 Sac | D27: 17 | E27: pcs | F27: =masterlist_log!P5 -> 649.95 | G27: =D27*F27 -> 11049.15 | N27: =SUM(G27:G30) -> 25991.28 | O27: =N27-26000 -> -8.72 | P27: Az Aşım
C28: 8x1500x6000 mm ST37 Sac | D28: 18 | E28: pcs | F28: =masterlist_log!P6 -> 565.44 | G28: =D28*F28 -> 10177.92
C29: 6x1500x6900 mm ST37 Sac | D29: 9 | E29: pcs | F29: =masterlist_log!P7 -> 487.49 | G29: =D29*F29 -> 4387.41
C30: 4x1500x8000 mm ST37 Sac | D30: 1 | E30: pcs | F30: =masterlist_log!P9 -> 376.8 | G30: =D30*F30 -> 376.8
A31: iskenderun_shp1 | B31: C19 | C31: 6x1500x6900 mm ST37 Sac | D31: 18 | E31: pcs | F31: =masterlist_log!P7 -> 487.49 | G31: =D31*F31 -> 8774.82 | N31: =SUM(G31:G34) -> 26200.05 | O31: =N31-26000 -> 200.05 | P31: Az Aşım
C32: 6x1500x6000 mm ST37 Sac | D32: 12 | E32: pcs | F32: =masterlist_log!P8 -> 423.75 | G32: =D32*F32 -> 5085
C33: 4x1500x8000 mm ST37 Sac | D33: 32 | E33: pcs | F33: =masterlist_log!P9 -> 376.8 | G33: =D33*F33 -> 12057.6
C34: 4x1500x6000 mm ST37 Sac | D34: 1 | E34: pcs | F34: =masterlist_log!P10 -> 282.63 | G34: =D34*F34 -> 282.63
A35: iskenderun_shp1 | B35: C20 | C35: 12x1500x8000 mm ST37 Sac | D35: 21 | E35: pcs | F35: =masterlist_log!P2 -> 1130.33 | G35: =D35*F35 -> 23736.93 | N35: =SUM(G35:G38) -> 26252.07 | O35: =N35-26000 -> 252.07 | P35: Az Aşım
C36: 12x1500x6900 mm ST37 Sac | D36: 2 | E36: pcs | F36: =masterlist_log!P3 -> 974.94 | G36: =D36*F36 -> 1949.88
C37: 3x1500x8000 mm ST37 Sac | D37: 1 | E37: pcs | F37: =masterlist_log!P11 -> 282.63 | G37: =D37*F37 -> 282.63
C38: 4x1500x6000 mm ST37 Sac | D38: 1 | E38: pcs | F38: =masterlist_log!P10 -> 282.63 | G38: =D38*F38 -> 282.63

Sheet Container_Plan
A1: Origin | B1: Shipment ID | C1: Container ID | D1: Container Type | E1: Material | F1: Qty 1 | G1: Unit 1 | H1: Qty 2 | I1: Unit 2 | J1: Unit Weight (kg) | K1: Total Weight (kg) | L1: Total Container Weight (kg) | M1: Payload Dif (kg) | N1: Pos
A2: İSKENDERUN | B2: iskSHT_shp1 | C2: C01 | D2: 40OT | E2: 6x1500x6900 St37 Sheet | F2: 53 | G2: pcs | J2: 487.49 | K2: =J2*F2 -> 25836.97 | L2: =K2 -> 25836.97 | M2: =L2-26000 -> -163.03 | N2: Limit Altı
A3: İSKENDERUN | B3: iskSHT_shp1 | C3: C02 | D3: 40OT | E3: 12x1500x8000 St37 Sheet | F3: 22 | G3: pcs | J3: 1130.33 | K3: =J3*F3 -> 24867.26 | L3: =SUM(K3:K4) -> 25715.15 | M3: =L3-26000 -> -284.85 | N3: Limit Altı
E4: 3x1500x8000 St37 Sheet | F4: 3 | G4: pcs | J4: 282.63 | K4: =J4*F4 -> 847.89
A5: İSKENDERUN | B5: iskSHT_shp1 | C5: C03 | D5: 40OT | E5: 12x1500x8000 St37 Sheet | F5: 22 | G5: pcs | J5: 1130.33 | K5: =J5*F5 -> 24867.26 | L5: =SUM(K5:K6) -> 25715.15 | M5: =L5-26000 -> -284.85 | N5: Limit Altı
E6: 3x1500x8000 St37 Sheet | F6: 3 | G6: pcs | J6: 282.63 | K6: =J6*F6 -> 847.89
A7: İSKENDERUN | B7: iskSHT_shp1 | C7: C04 | D7: 40OT | E7: 12x1500x8000 St37 Sheet | F7: 22 | G7: pcs | J7: 1130.33 | K7: =J7*F7 -> 24867.26 | L7: =SUM(K7:K8) -> 25715.15 | M7: =L7-26000 -> -284.85 | N7: Limit Altı
E8: 3x1500x8000 St37 Sheet | F8: 3 | G8: pcs | J8: 282.63 | K8: =J8*F8 -> 847.89
A9: İSKENDERUN | B9: iskSHT_shp1 | C9: C05 | D9: 40OT | E9: 12x1500x8000 St37 Sheet | F9: 22 | G9: pcs | J9: 1130.33 | K9: =J9*F9 -> 24867.26 | L9: =SUM(K9:K10) -> 25715.15 | M9: =L9-26000 -> -284.85 | N9: Limit Altı
E10: 3x1500x8000 St37 Sheet | F10: 3 | G10: pcs | J10: 282.63 | K10: =J10*F10 -> 847.89
A11: İSKENDERUN | B11: iskSHT_shp1 | C11: C06 | D11: 40OT | E11: 12x1500x8000 St37 Sheet | F11: 22 | G11: pcs | J11: 1130.33 | K11: =J11*F11 -> 24867.26 | L11: =SUM(K11:K12) -> 25715.15 | M11: =L11-26000 -> -284.85 | N11: Limit Altı
E12: 3x1500x8000 St37 Sheet | F12: 3 | G12: pcs | J12: 282.63 | K12: =J12*F12 -> 847.89
A13: İSKENDERUN | B13: iskSHT_shp1 | C13: C07 | D13: 40OT | E13: 10x1500x6900 St37 Sheet | F13: 31 | G13: pcs | J13: 812.44 | K13: =J13*F13 -> 25185.64 | L13: =SUM(K13:K14) -> 25750.9 | M13: =L13-26000 -> -249.1 | N13: Limit Altı
E14: 3x1500x8000 St37 Sheet | F14: 2 | G14: pcs | J14: 282.63 | K14: =J14*F14 -> 565.26
A15: İSKENDERUN | B15: iskSHT_shp1 | C15: C08 | D15: 40OT | E15: 10x1500x6900 St37 Sheet | F15: 31 | G15: pcs | J15: 812.44 | K15: =J15*F15 -> 25185.64 | L15: =SUM(K15:K16) -> 25750.9 | M15: =L15-26000 -> -249.1 | N15: Limit Altı
E16: 3x1500x8000 St37 Sheet | F16: 2 | G16: pcs | J16: 282.63 | K16: =J16*F16 -> 565.26
A17: İSKENDERUN | B17: iskSHT_shp1 | C17: C09 | D17: 40OT | E17: 10x1500x6900 St37 Sheet | F17: 16 | G17: pcs | J17: 812.44 | K17: =J17*F17 -> 12999.04 | L17: =SUM(K17:K18) -> 25998.04 | M17: =L17-26000 -> -1.96 | N17: Limit Altı
E18: 8x1500x6900 St37 Sheet | F18: 20 | G18: pcs | J18: 649.95 | K18: =J18*F18 -> 12999
A19: İSKENDERUN | B19: iskSHT_shp1 | C19: C10 | D19: 40OT | E19: 8x1500x6900 St37 Sheet | F19: 39 | G19: pcs | J19: 649.95 | K19: =J19*F19 -> 25348.05 | L19: =SUM(K19:K20) -> 25630.68 | M19: =L19-26000 -> -369.32 | N19: Limit Altı
E20: 3x1500x8000 St37 Sheet | F20: 1 | G20: pcs | J20: 282.63 | K20: =J20*F20 -> 282.63
A21: İSKENDERUN | B21: iskSHT_shp1 | C21: C11 | D21: 40OT | E21: 6x1500x6900 St37 Sheet | F21: 52 | G21: pcs | J21: 487.49 | K21: =J21*F21 -> 25349.48 | L21: =SUM(K21:K22) -> 25632.11 | M21: =L21-26000 -> -367.89 | N21: Limit Altı
E22: 3x1500x8000 St37 Sheet | F22: 1 | G22: pcs | J22: 282.63 | K22: =J22*F22 -> 282.63
A23: İSKENDERUN | B23: iskSHT_shp1 | C23: C12 | D23: 40OT | E23: 4x1500x8000 St37 Sheet | F23: 68 | G23: pcs | J23: 376.8 | K23: =J23*F23 -> 25622.4 | L23: =SUM(K23:K24) -> 25905.03 | M23: =L23-26000 -> -94.97 | N23: Limit Altı
E24: 3x1500x8000 St37 Sheet | F24: 1 | G24: pcs | J24: 282.63 | K24: =J24*F24 -> 282.63
A25: İSKENDERUN | B25: iskSHT_shp1 | C25: C13 | D25: 40OT | E25: 12x1500x8000 St37 Sheet | F25: 21 | G25: pcs | J25: 1130.33 | K25: =J25*F25 -> 23736.93 | L25: =SUM(K25:K27) -> 25969.44 | M25: =L25-26000 -> -30.56 | N25: Limit Altı
E26: 12x1500x6900 St37 Sheet | F26: 2 | G26: pcs | J26: 974.94 | K26: =J26*F26 -> 1949.88
E27: 4x1500x6000 St37 Sheet | F27: 1 | G27: pcs | J27: 282.63 | K27: =J27*F27 -> 282.63
A28: İSKENDERUN | B28: iskSHT_shp1 | C28: C14 | D28: 40OT | E28: 12x1500x6900 St37 Sheet | F28: 25 | G28: pcs | J28: 974.94 | K28: =J28*F28 -> 24373.5 | L28: =SUM(K28:K30) -> 25588.71 | M28: =L28-26000 -> -411.29 | N28: Limit Altı
E29: 8x1500x6900 St37 Sheet | F29: 1 | G29: pcs | J29: 649.95 | K29: =J29*F29 -> 649.95
E30: 3x1500x8000 St37 Sheet | F30: 2 | G30: pcs | J30: 282.63 | K30: =J30*F30 -> 565.26
A31: İSKENDERUN | B31: iskSHT_shp1 | C31: C15 | D31: 40OT | E31: 12x1500x6900 St37 Sheet | F31: 25 | G31: pcs | J31: 974.94 | K31: =J31*F31 -> 24373.5 | L31: =SUM(K31:K33) -> 25588.71 | M31: =L31-26000 -> -411.29 | N31: Limit Altı
E32: 8x1500x6900 St37 Sheet | F32: 1 | G32: pcs | J32: 649.95 | K32: =J32*F32 -> 649.95
E33: 3x1500x8000 St37 Sheet | F33: 2 | G33: pcs | J33: 282.63 | K33: =J33*F33 -> 565.26
A34: İSKENDERUN | B34: iskSHT_shp1 | C34: C16 | D34: 40OT | E34: 12x1500x6900 St37 Sheet | F34: 25 | G34: pcs | J34: 974.94 | K34: =J34*F34 -> 24373.5 | L34: =SUM(K34:K36) -> 25588.71 | M34: =L34-26000 -> -411.29 | N34: Limit Altı
E35: 8x1500x6900 St37 Sheet | F35: 1 | G35: pcs | J35: 649.95 | K35: =J35*F35 -> 649.95
E36: 3x1500x8000 St37 Sheet | F36: 2 | G36: pcs | J36: 282.63 | K36: =J36*F36 -> 565.26
A37: İSKENDERUN | B37: iskSHT_shp1 | C37: C17 | D37: 40OT | E37: 6x1500x6900 St37 Sheet | F37: 5 | G37: pcs | J37: 487.49 | K37: =J37*F37 -> 2437.45 | L37: =SUM(K37:K39) -> 25985.65 | M37: =L37-26000 -> -14.35 | N37: Limit Altı
E38: 6x1500x6000 St37 Sheet | F38: 12 | G38: pcs | J38: 423.75 | K38: =J38*F38 -> 5085
E39: 4x1500x8000 St37 Sheet | F39: 49 | G39: pcs | J39: 376.8 | K39: =J39*F39 -> 18463.2
A40: İSKENDERUN | B40: iskSHT_shp1 | C40: C18 | D40: 40OT | E40: 4x1500x8000 St37 Sheet | F40: 16 | G40: pcs | J40: 376.8 | K40: =J40*F40 -> 6028.8 | L40: =SUM(K40:K42) -> 25812.9 | M40: =L40-26000 -> -187.1 | N40: Limit Altı
...

Sheet Shipment_View
A1: Project | B1: WBS Code | C1: Deliverable Type | D1: Shipment ID | E1: Origin | F1: Supplier | G1: Cargo Group | H1: Material | I1: Description | J1: Qty | K1: Unit | L1: Unit Weight (kg) | M1: Total Weight (kg) | N1: Length (m) | O1: Width | P1: Height | Q1: Package Type | R1: Package Qty | S1: HS Code (GTIP) | T1: Notes

Sheet Packing_List
A1: Package No | B1: Description | C1: Qty | D1: Net Weight | E1: Gross Weight | F1: Dimensions | G1: HS Code
